Workbook

Sheet 兩期比較
A1: 賀毅科技股份有限公司
A2: 損益表實際數-兩期比較
B5: 2017 | T5: 2017 | U5: 2016 | AM5: 2016 | AN5: 2015 | BF5: 2015 | BG5: 2014 | BY5: 2014 | BZ5: 2013 | CR5: 2013 | CS5: 2012 | DL5: 2013 vs 2012 | DM5: 2013 vs 2012 | DN5: 2014 vs 2013 | DO5: 2014 vs 2013 | DP5: 2015 vs 2014 | DQ5: 2015 vs 2014 | DR5: 2016 vs 2015 | DS5: 2016 vs 2015 | DT5: 2017 vs 2016 | DU5: 2017 vs 2016
B6: Jan | C6: Feb | D6: Mar | E6: Q1 | F6: Apr | G6: May | H6: Jun | I6: Q2 | J6: Jul | K6: Aug | L6: Sep | M6: Q3 | N6: Oct | O6: Nov | P6: Dec | Q6: Q4 | R6: HF | S6: Q1~Q3 | T6: 全年合計 | U6: Jan | V6: Feb | W6: Mar | X6: Q1 | Y6: Apr | Z6: May | AA6: Jun | AB6: Q2 | AC6: Jul | AD6: Aug | AE6: Sep | AF6: Q3 | AG6: Oct | AH6: Nov | AI6: Dec | AJ6: Q4 | AK6: HF | AL6: Q1~Q3 | AM6: 全年合計 | AN6: Jan | AO6: Feb | AP6: Mar | AQ6: Q1 | AR6: Apr | AS6: May | AT6: Jun | AU6: Q2 | AV6: Jul | AW6: Aug | AX6: Sep | AY6: Q3 | AZ6: Oct | BA6: Nov | BB6: Dec | BC6: Q4 | BD6: HF | BE6: Q1~Q3 | BF6: 全年合計 | BG6: Jan | BH6: Feb | BI6: Mar | BJ6: Q1 | BK6: Apr | BL6: May | BM6: Jun | BN6: Q2 | BO6: Jul | BP6: Aug | BQ6: Sep | BR6: Q3 | BS6: Oct | BT6: Nov | BU6: Dec | BV6: Q4 | BW6: HF | BX6: Q1~Q3 | BY6: 全年合計 | BZ6: Jan | CA6: Feb | CB6: Mar | CC6: Q1 | CD6: Apr | CE6: May | CF6: Jun | CG6: Q2 | CH6: Jul | CI6: Aug | CJ6: Sep | CK6: Q3 | CL6: Oct | CM6: Nov | CN6: Dec | CO6: Q4 | CP6: HF | CQ6: Q1-Q3 | CR6: 全年合計 | CS6: Jan | CT6: Feb | CU6: Mar | CV6: Q1 | CW6: Apr | CX6: May | CY6: Jun | CZ6: Q2 | DA6: Jul | DB6: Aug | DC6: Sep | DD6: Q3 | DE6: Oct | DF6: Nov | DG6: Dec | DH6: Q4 | DI6: HF | DJ6: Q1-Q3 | DK6: 全年合計 | DL6: 兩期差異 | DM6: 變動率 | DN6: 兩期差異 | DO6: 變動率 | DP6: 兩期差異 | DQ6: 變動率 | DR6: 兩期差異 | DS6: 變動率 | DT6: 兩期差異 | DU6: 變動率
A7: 營業收入
A8: POS BU1 | B8: ='2017 預算'!C8 -> 4501975 | C8: ='2017 預算'!F8 -> 4505830 | D8: ='2017 預算'!I8 -> 28499391 | E8: =SUM(B8:D8) -> 37507196 | F8: ='2017 預算'!O8 -> 4764667 | G8: ='2017 預算'!R8 -> 12977409 | H8: ='2017 預算'!U8 -> 14460790 | I8: =SUM(F8:H8) -> 32202866 | J8: ='2017 預算'!AA8 -> 5214450 | K8: ='2017 預算'!AD8 -> 9660426 | L8: ='2017 預算'!AG8 -> 0 | M8: =SUM(J8:L8) -> 14874876 | N8: ='2017 預算'!AM8 -> 0 | O8: ='2017 預算'!AP8 -> 0 | P8: ='2017 預算'!AS8 -> 0 | Q8: =SUM(N8:P8) -> 0 | R8: =E8+I8 -> 69710062 | S8: =E8+I8+M8 -> 84584938 | T8: =E8+I8+M8+Q8 -> 84584938 | U8: 7568868 | V8: 7155302 | W8: 22046986 | X8: 36771156 | Y8: 11551044 | Z8: 14260246 | AA8: 21719958 | AB8: 47531248 | AC8: 13786404 | AD8: 21656673 | AE8: 15427205 | AF8: 50870282 | AG8: 4186210 | AH8: 5821279 | AI8: 30182961 | AJ8: 40190450 | AK8: 84302404 | AL8: 135172686 | AM8: 175363136 | AN8: 12425392 | AO8: 6060616 | AP8: 18291729 | AQ8: 36777737 | AR8: 8808531 | AS8: 7925551 | AT8: 18886402 | AU8: 35620484 | AV8: 13325525 | AW8: 7233105 | AX8: 10558033 | AY8: 15698327 | AZ8: 19482901 | BA8: 6159809 | BB8: 26911870 | BC8: 33407056 | BD8: 52300785 | BE8: 67999112 | BF8: =148961797-911580+9687205-1667958 -> 156069464 | BG8: 6422490 | BH8: 6090616 | BI8: 15870998 | BJ8: 28384104 | BK8: 3757141 | BL8: 9765509 | BM8: 11582309 | BN8: 25104959 | BO8: 2245168 | BP8: 6467856 | BQ8: 13721380 | BR8: 22434404 | BS8: 5707503 | BT8: 7608321 | BU8: 13505294 | BV8: 26821118 | BW8: 53489063 | BX8: 75923467 | BY8: =234221549 -> 234221549 | BZ8: 11225175 | CA8: 2996876 | CB8: 5700706 | CC8: 19922757 | CD8: 11202404 | CE8: 5034671 | CF8: 21070553 | CG8: 37307628 | CH8: 6330444 | CI8: 6376788 | CJ8: 11013477 | CK8: 23720709 | CL8: 8155671 | CM8: 13696999 | CN8: 12587867 | CO8: 34440537 | CP8: 57230385 | CQ8: 80951094 | CR8: =235997450-243098 -> 235754352 | CS8: 3024966 | CT8: 8161276 | CU8: 12362451 | CV8: =SUM(CS8:CU8) -> 23548693 | CW8: 6154342 | CX8: 8824445 | CY8: 13820153 | CZ8: =SUM(CW8:CY8) -> 28798940 | DA8: =7680132-1561 -> 7678571 | DB8: 8540673 | DC8: 7199353 | DD8: =SUM(DA8:DC8) -> 23418597 | DE8: 4184659 | DF8: 4063796 | DG8: 12017888 | DH8: =SUM(DE8:DG8) -> 20266343 | DI8: =CV8+CZ8 -> 52347633 | DJ8: =CV8+CZ8+DD8 -> 75766230 | DK8: =DH8+DJ8 -> 96032573 | DL8: =CR8-DK8 -> 139721779 | DM8: =DL8/DK8 -> 1.4549415 | DN8: =BY8-CR8 -> -1532803 | DO8: =DN8/CR8 -> -0.0065016955 | DP8: =BF8-BY8 -> -78152085 | DQ8: =DP8/BY8 -> -0.33366736 | DR8: =AM8-BE8 -> 107364024 | DS8: =DR8/BF8 -> 0.6879246 | DT8: =C8-V8 -> -2649472 | DU8: =DT8/BH8 -> -0.43500887
A9: POS BU2 | B9: ='2017 預算'!C9 -> 0 | C9: ='2017 預算'!F9 -> 0 | D9: ='2017 預算'!I9 -> 0 | E9: =SUM(B9:D9) -> 0 | F9: ='2017 預算'!O9 -> 0 | G9: ='2017 預算'!R9 -> 0 | H9: ='2017 預算'!U9 -> 0 | I9: =SUM(F9:H9) -> 0 | J9: ='2017 預算'!AA9 -> 0 | K9: ='2017 預算'!AD9 -> 0 | L9: ='2017 預算'!AG9 -> 0 | M9: =SUM(J9:L9) -> 0 | N9: ='2017 預算'!AM9 -> 0 | O9: ='2017 預算'!AP9 -> 0 | P9: ='2017 預算'!AS9 -> 0 | Q9: =SUM(N9:P9) -> 0 | R9: =E9+I9 -> 0 | S9: =E9+I9+M9 -> 0 | T9: =E9+I9+M9+Q9 -> 0 | U9: 47882 | V9: 200000 | W9: 617337 | X9: 865219 | Y9: 69571 | Z9: 1347767 | AA9: 1089519 | AB9: 2506857 | AC9: 0 | AD9: 0 | AE9: 0 | AF9: 0 | AG9: 0 | AH9: 0 | AI9: 0 | AJ9: 0 | AK9: 3372076 | AL9: 3372076 | AM9: 3372076 | AN9: 0 | AO9: 0 | AP9: 2000 | AQ9: 2000 | AR9: -28216 | AS9: 160200 | AT9: 0 | AU9: 131984 | AV9: 7155 | AW9: 0 | AX9: 102990 | AY9: 2412808 | AZ9: 607144 | BA9: 168035 | BB9: 648650 | BC9: 2941828 | BD9: 4332569 | BE9: 6745377 | BF9: 1667958 | BG9: 1147616 | BH9: 5294 | BJ9: 1152910 | BK9: 201971 | BL9: 846160 | BM9: 1008235 | BN9: 2056366 | BO9: 515313 | BP9: 1540385 | BR9: 2055698 | BS9: 725640 | BT9: 139040 | BU9: 1828602 | BV9: 2693282 | BW9: 3209276 | BX9: 5264974 | BY9: 7958256 | BZ9: 2815145 | CA9: 1588836 | CB9: 4745076 | CC9: 9149057 | CD9: 1736630 | CE9: 1331798 | CF9: 1322372 | CG9: 4390800 | CH9: 1018802 | CI9: 917921 | CJ9: 1625950 | CK9: 3562673 | CL9: 1890820 | CM9: 1110129 | CN9: 1423862 | CO9: 4424811 | CP9: 13539857 | CQ9: 17102530 | CR9: 21527341 | CS9: 361348 | CT9: 6001628 | CU9: 4814710 | CV9: =SUM(CS9:CU9) -> 11177686 | CW9: 1289405 | CX9: 7267230 | CY9: 2328392 | CZ9: =SUM(CW9:CY9) -> 10885027 | DA9: 5152007 | DB9: 1590517 | DC9: 1209432 | DD9: =SUM(DA9:DC9) -> 7951956 | DE9: 1165690 | DF9: 1478391 | DG9: 3472989 | DH9: =SUM(DE9:DG9) -> 6117070 | DI9: =CV9+CZ9 -> 22062713 | DJ9: =CV9+CZ9+DD9 -> 30014669 | DK9: =DH9+DJ9 -> 36131739 | DL9: =CR9-DK9 -> -14604398 | DM9: =DL9/DK9 -> -0.40419859 | DN9: =BY9-CR9 -> -13569085 | DO9: =DN9/CR9 -> -0.63031867 | DP9: =BF9-BY9 -> -6290298 | DQ9: =DP9/BY9 -> -0.79041162 | DR9: =AM9-BE9 -> -3373301 | DS9: =DR9/BF9 -> -2.0224136 | DT9: =C9-V9 -> -200000 | DU9: =DT9/BH9 -> -37.778617
A10: POS BU3-SE | B10: ='2017 預算'!C10 -> 51078473 | C10: ='2017 預算'!F10 -> 42980961 | D10: ='2017 預算'!I10 -> 30561593 | E10: =SUM(B10:D10) -> 124621027 | F10: ='2017 預算'!O10 -> 59543429 | G10: ='2017 預算'!R10 -> 37166163 | H10: ='2017 預算'!U10 -> 69467942 | I10: =SUM(F10:H10) -> 166177534 | J10: ='2017 預算'!AA10 -> 85004893 | K10: ='2017 預算'!AD10 -> 65629388 | L10: ='2017 預算'!AG10 -> 0 | M10: =SUM(J10:L10) -> 150634281 | N10: ='2017 預算'!AM10 -> 0 | O10: ='2017 預算'!AP10 -> 0 | P10: ='2017 預算'!AS10 -> 0 | Q10: =SUM(N10:P10) -> 0 | R10: =E10+I10 -> 290798561 | S10: =E10+I10+M10 -> 441432842 | T10: =E10+I10+M10+Q10 -> 441432842 | U10: 28946283 | V10: 33831112 | W10: 45177730 | X10: 107955125 | Y10: 30265898 | Z10: 44866539 | AA10: 32987432 | AB10: 108119869 | AC10: 33576273 | AD10: 43602105 | AE10: 35726953 | AF10: 112905331 | AG10: 38830959 | AH10: 58240463 | AI10: 58004207 | AJ10: 155075629 | AK10: 216074994 | AL10: 328980325 | AM10: 484055954 | AN10: 7671588 | AO10: 22355849 | AP10: 42802355 | AQ10: 72829792 | AR10: 40297963 | AS10: 25044659 | AT10: 40268975 | AU10: 105611597 | AV10: 15892559 | AW10: 17462298 | AX10: 20498946 | AY10: 53853803 | AZ10: 4730170 | BA10: 18339741 | BB10: 54328086 | BC10: 77397997 | BD10: 177529809 | BE10: 231383612 | BF10: =308781609+911580 -> 309693189 | BG10: 0 | BH10: 51516 | BI10: 40902 | BJ10: 92418 | BK10: 258862 | BL10: 593364 | BN10: 852226 | BP10: 0 | BQ10: 292986 | BR10: 292986 | BS10: 164416 | BT10: 6590499 | BU10: 11434896 | BV10: 18189811 | BW10: 944644 | BX10: 1237630 | BY10: 19427441 | BZ10: 6988375 | CA10: 200790 | CB10: 4516513 | CC10: 11705678 | CD10: 6113021 | CE10: 6432539 | CF10: 4156199 | CG10: 16701759 | CH10: 6931568 | CI10: 2523453 | CJ10: 253841 | CK10: 9708862 | CL10: 187616 | CM10: 0 | CN10: 1711568 | CO10: 1899184 | CP10: 28407437 | CQ10: 38116299 | CR10: 40015483 | CS10: 8379295 | CT10: 7870561 | CU10: 3387827 | CV10: =SUM(CS10:CU10) -> 19637683 | CW10: 6860711 | CX10: 928044 | CY10: 370 | CZ10: =SUM(CW10:CY10) -> 7789125 | DA10: 8890848 | DB10: 1694 | DC10: 3305503 | DD10: =SUM(DA10:DC10) -> 12198045 | DE10: 3638545 | DF10: 3263583 | DG10: 715729 | DH10: =SUM(DE10:DG10) -> 7617857 | DI10: =CV10+CZ10 -> 27426808 | DJ10: =CV10+CZ10+DD10 -> 39624853 | DK10: =DH10+DJ10 -> 47242710 | DL10: =CR10-DK10 -> -7227227 | DM10: =DL10/DK10 -> -0.15298079 | DN10: =BY10-CR10 -> -20588042 | DO10: =DN10/CR10 -> -0.5145019 | DP10: =BF10-BY10 -> 290265748 | DQ10: =DP10/BY10 -> 14.941018 | DR10: =AM10-BE10 -> 252672342 | DS10: =DR10/BF10 -> 0.81587956 | DT10: =C10-V10 -> 9149849 | DU10: =DT10/BH10 -> 177.61179
A11: POS BU4-AB | B11: ='2017 預算'!C11 -> 4662544 | C11: ='2017 預算'!F11 -> 5540923 | D11: ='2017 預算'!I11 -> 4643464 | E11: =SUM(B11:D11) -> 14846931 | F11: ='2017 預算'!O11 -> 3036598 | G11: ='2017 預算'!R11 -> 3094664 | H11: ='2017 預算'!U11 -> 3477355 | I11: =SUM(F11:H11) -> 9608617 | J11: ='2017 預算'!AA11 -> 8018284 | K11: ='2017 預算'!AD11 -> 6841562 | L11: ='2017 預算'!AG11 -> 0 | M11: =SUM(J11:L11) -> 14859846 | N11: ='2017 預算'!AM11 -> 0 | O11: ='2017 預算'!AP11 -> 0 | P11: ='2017 預算'!AS11 -> 0 | Q11: =SUM(N11:P11) -> 0 | R11: =E11+I11 -> 24455548 | S11: =E11+I11+M11 -> 39315394 | T11: =E11+I11+M11+Q11 -> 39315394 | U11: 336518 | V11: 0 | W11: 917455 | X11: 1253973 | Y11: 165929 | Z11: 194449 | AA11: 184496 | AB11: 544874 | AC11: 3121546 | AD11: 2726096 | AE11: 2871440 | AF11: 8719082 | AG11: 5646258 | AH11: 4131420 | AI11: 5177125 | AJ11: 14954803 | AK11: 1798847 | AL11: 10517929 | AM11: 25472732 | DT11: =C11-V11 -> 5540923 | DU11: =DT11/BH11 -> #DIV/0!
A12: 維修收入 | B12: ='2017 預算'!C12 -> 3959 | C12: ='2017 預算'!F12 -> 43786 | D12: ='2017 預算'!I12 -> 27522 | E12: =SUM(B12:D12) -> 75267 | F12: ='2017 預算'!O12 -> 20986 | G12: ='2017 預算'!R12 -> 43107 | H12: ='2017 預算'!U12 -> 81879 | I12: =SUM(F12:H12) -> 145972 | J12: ='2017 預算'!AA12 -> 3539 | K12: ='2017 預算'!AD12 -> 3539 | L12: ='2017 預算'!AG12 -> 0 | M12: =SUM(J12:L12) -> 7078 | N12: ='2017 預算'!AM12 -> 0 | O12: ='2017 預算'!AP12 -> 0 | P12: ='2017 預算'!AS12 -> 0 | Q12: =SUM(N12:P12) -> 0 | R12: =E12+I12 -> 221239 | S12: =E12+I12+M12 -> 228317 | T12: =E12+I12+M12+Q12 -> 228317 | U12: 56092 | V12: 17262 | W12: 39190 | X12: 112544 | Y12: 20812 | Z12: 20562 | AA12: 44666 | AB12: 86040 | AC12: 22597 | AD12: 18552 | AE12: 20564 | AF12: 61713 | AG12: 14160 | AH12: 26848 | AI12: 3539 | AJ12: 44547 | AK12: 198584 | AL12: 260297 | AM12: 304844 | AN12: 24444 | AO12: 0 | AP12: 2290 | AQ12: 26734 | AR12: 5298 | AS12: 30941 | AT12: 15609 | AU12: 51848 | AV12: 55189 | AW12: 12330 | AX12: 0 | AY12: 67519 | AZ12: 67324 | BA12: 32786 | BB12: 27151 | BC12: 127261 | BD12: 78582 | BE12: 146101 | BF12: 273362 | BG12: 3400 | BH12: 1544 | BI12: 114383 | BJ12: 119327 | BK12: -93751 | BL12: 1200 | BN12: -92551 | BO12: 16392 | BP12: 19966 | BR12: 36358 | BS12: 28734 | BT12: 0 | BU12: 2200 | BV12: 30934 | BW12: 26776 | BX12: 63134 | BY12: 94068 | BZ12: 16138 | CA12: 24772 | CB12: 10496 | CC12: 51406 | CD12: 7827 | CE12: 29615 | CF12: 27200 | CG12: 64642 | CH12: 46077 | CI12: 19847 | CJ12: 10952 | CK12: 76876 | CL12: 9334 | CM12: 5070 | CN12: 35770 | CO12: 50174 | CP12: 116048 | CQ12: 192924 | CR12: 243098 | CS12: 159175 | CT12: 20120 | CU12: 92201 | CV12: =SUM(CS12:CU12) -> 271496 | CW12: 48886 | CX12: 12677 | CY12: 26804 | CZ12: =SUM(CW12:CY12) -> 88367 | DA12: 59329 | DB12: =18410+465664 -> 484074 | DC12: 31580 | DD12: =SUM(DA12:DC12) -> 574983 | DE12: 18910 | DF12: 31199 | DG12: 11854 | DH12: =SUM(DE12:DG12) -> 61963 | DI12: =CV12+CZ12 -> 359863 | DJ12: =CV12+CZ12+DD12 -> 934846 | DK12: =DH12+DJ12 -> 996809 | DL12: =CR12-DK12 -> -753711 | DM12: =DL12/DK12 -> -0.75612379 | DN12: =BY12-CR12 -> -149030 | DO12: =DN12/CR12 -> -0.61304494 | DP12: =BF12-BY12 -> 179294 | DQ12: =DP12/BY12 -> 1.9060042 | DR12: =AM12-BE12 -> 158743 | DS12: =DR12/BF12 -> 0.58070617 | DT12: =C12-V12 -> 26524 | DU12: =DT12/BH12 -> 17.178756
A13: 營業收入合計 | B13: =SUM(B8:B12) -> 60246951 | C13: =SUM(C8:C12) -> 53071500 | D13: =SUM(D8:D12) -> 63731970 | E13: =SUM(B13:D13) -> 177050421 | F13: =SUM(F8:F12) -> 67365680 | G13: =SUM(G8:G12) -> 53281343 | H13: =SUM(H8:H12) -> 87487966 | I13: =SUM(I8:I12) -> 2.0813499e+08 | J13: =SUM(J8:J12) -> 98241166 | K13: =SUM(K8:K12) -> 82134915 | L13: =SUM(L8:L12) -> 0 | M13: =SUM(M8:M12) -> 180376081 | ... S13: =SUM(S8:S12) -> 5.6556149e+08 | T13: =E13+I13+M13+Q13 -> 5.6556149e+08 | U13: 36955643 | V13: 41203676 | W13: 68798698 | X13: 146958017 | Y13: 42073254 | Z13: 60689563 | AA13: 56026071 | AB13: 158788888 | AC13: 50506820 | AD13: 68003426 | AE13: 54046162 | AF13: 172556408 | AG13: 48677587 | AH13: 68220010 | AI13: 93367832 | AJ13: 210265429 | AK13: 305746905 | AL13: 478303313 | AM13: 688568742 | AN13: 20121424 | AO13: 28416465 | AP13: 61098374 | AQ13: 109636263 | AR13: 49083576 | AS13: 33161351 | AT13: 59170986 | AU13: 141415913 | AV13: 29280428 | AW13: 24707733 | AX13: 31159969 | AY13: 85148130 | AZ13: 24887539 | BA13: 24700371 | BB13: 81915757 | BC13: 131503667 | BD13: 251052176 | BE13: 336200306 | BF13: 467703973 | BG13: 15348219 | BH13: 13938223 | BI13: 24821394 | BJ13: 54107836 | BK13: 11791659 | BL13: 33172666 | BM13: 33810586 | BN13: 78774911 | BO13: 20106580 | BP13: 20272573 | BQ13: 23031798 | BR13: 63410951 | BS13: 10158595 | BT13: 20830745 | BU13: 34324208 | BV13: 65313548 | BW13: 132882747 | BX13: 196293698 | BY13: 261607246 | BZ13: 39991069 | CA13: 16193946 | CB13: 25159481 | CC13: 81344496 | CD13: 28150265 | CE13: 26063114 | CF13: 34956546 | CG13: 89169925 | CH13: 23865164 | CI13: 20353037 | CJ13: 21146738 | CK13: 65364939 | CL13: 13204931 | CM13: 25585809 | CN13: 22870174 | CO13: 61660914 | CP13: 170514421 | CQ13: 235879360 | CR13: 297540274 | CS13: =SUM(CS8:CS12) -> 11924784 | CT13: =SUM(CT8:CT12) -> 22053585 | CU13: =SUM(CU8:CU12) -> 20657189 | CV13: =SUM(CS13:CU13) -> 54635558 | CW13: =SUM(CW8:CW12) -> 14353344 | CX13: =SUM(CX8:CX12) -> 17032396 | CY13: =SUM(CY8:CY12) -> 16175719 | CZ13: =SUM(CW13:CY13) -> 47561459 | DA13: =SUM(DA8:DA12) -> 21780755 | DB13: =SUM(DB8:DB12) -> 10616958 | DC13: =SUM(DC8:DC12) -> 11745868 | DD13: =SUM(DA13:DC13) -> 44143581 | DE13: =SUM(DE8:DE12) -> 9007804 | DF13: =SUM(DF8:DF12) -> 8836969 | DG13: =SUM(DG8:DG12) -> 16218460 | DH13: =SUM(DE13:DG13) -> 34063233 | DI13: =CV13+CZ13 -> 102197017 | DJ13: =CV13+CZ13+DD13 -> 146340598 | DK13: =DH13+DJ13 -> 180403831 | DL13: =CR13-DK13 -> 117136443 | DM13: =DL13/DK13 -> 0.64930131 | DN13: =BY13-CR13 -> -35933028 | DO13: =DN13/CR13 -> -0.12076694 | DP13: =BF13-BY13 -> 206096727 | DQ13: =DP13/BY13 -> 0.7878097 | DR13: =AM13-BE13 -> 352368436 | DS13: =DR13/BF13 -> 0.75340056 | DT13: =C13-V13 -> 11867824 | DU13: =DT13/BH13 -> 0.8514589
A14: 營業成本 | B14: ='2017 預算'!C14 -> 55646869 | C14: ='2017 預算'!F14 -> 52320171 | D14: ='2017 預算'!I14 -> 53472402 | E14: =SUM(B14:D14) -> 161439442 | F14: ='2017 預算'!O14 -> 59947315 | G14: ='2017 預算'!R14 -> 46938901 | H14: ='2017 預算'!U14 -> 76556480 | I14: =SUM(F14:H14) -> 183442696 | J14: ='2017 預算'!AA14 -> 87191630 | K14: ='2017 預算'!AD14 -> 70950644 | L14: ='2017 預算'!AG14 -> 0 | M14: =SUM(J14:L14) -> 158142274 | N14: ='2017 預算'!AM14 -> 0 | O14: ='2017 預算'!AP14 -> 0 | P14: ='2017 預算'!AS14 -> 0 | Q14: =SUM(N14:P14) -> 0 | R14: =E14+I14 -> 344882138 | S14: =E14+I14+M14 -> 503024412 | T14: =E14+I14+M14+Q14 -> 503024412 | U14: 31243974 | V14: 39556792 | W14: 52692537 | X14: 123493303 | Y14: 34206151 | Z14: 45727500 | AA14: 41354713 | AB14: 121288364 | AC14: 41942955 | AD14: 55560009 | AE14: 46024712 | AF14: 143527676 | AG14: 43268327 | AH14: 55123597 | AI14: =76583648+99025 -> 76682673 | AJ14: =174975572+99025 -> 175074597 | AK14: 244781667 | AL14: =388309343 -> 388309343 | AM14: =563284915+99025 -> 563383940 | AN14: 16692801 | AO14: 27049095 | AP14: 52912401 | AQ14: 96654297 | AR14: 41243729 | AS14: 27959377 | AT14: 48091078 | AU14: 117294184 | AV14: 25227381 | AW14: 22845429 | AX14: 26427403 | AY14: 74500213 | AZ14: 22033948 | BA14: 21944427 | BB14: 58869666 | BC14: 102848041 | BD14: 213948481 | BE14: 288448694 | BF14: 391296735 | BG14: 10931860 | BH14: 13807347 | BI14: 18299301 | BJ14: 43038508 | BK14: 8610490 | BL14: 25147200 | BM14: 28498589 | BN14: 62256279 | BO14: 14570867 | BP14: 15557467 | BQ14: 16721204 | BR14: 46849538 | BS14: 8444860 | BT14: 19319096 | BU14: 23017369 | BV14: 50781325 | BW14: 105294787 | BX14: 152144325 | BY14: 202925650 | BZ14: 31221524 | CA14: 13904326 | CB14: 18049345 | CC14: 63175195 | CD14: 22365591 | CE14: 22511921 | CF14: 26637307 | CG14: 71514819 | CH14: 18548359 | CI14: 14179951 | CJ14: 20303116 | CK14: 53031426 | CL14: 16862329 | CM14: 21667624 | CN14: 13670900 | CO14: 52200853 | CP14: 134690014 | CQ14: 187721440 | CR14: 239922293 | CS14: 19195795 | CT14: 28091041 | CU14: =[1]TWN_IS!F88 -> 24033698 | CV14: =SUM(CS14:CU14) -> 71320534 | CW14: 18464912 | CX14: 24205476 | CY14: 23689240 | CZ14: =SUM(CW14:CY14) -> 66359628 | DA14: 20158024 | DB14: 18073992 | DC14: 22353248 | DD14: =SUM(DA14:DC14) -> 60585264 | DE14: 20398077 | DF14: 14796955 | DG14: 17035791 | DH14: =SUM(DE14:DG14) -> 52230823 | DI14: =CV14+CZ14 -> 137680162 | DJ14: =CV14+CZ14+DD14 -> 198265426 | DK14: =DH14+DJ14 -> 250496249 | DL14: =CR14-DK14 -> -10573956 | DM14: =DL14/DK14 -> -0.042212033 | DN14: =BY14-CR14 -> -36996643 | DO14: =DN14/CR14 -> -0.15420261 | DP14: =BF14-BY14 -> 188371085 | DQ14: =DP14/BY14 -> 0.92827637 | DR14: =AM14-BE14 -> 274935246 | DS14: =DR14/BF14 -> 0.70262596 | DT14: =C14-V14 -> 12763379 | DU14: =DT14/BH14 -> 0.9243904
A15: ▲ 營業毛利： | B15: =B13-B14 -> 4600082 | C15: =C13-C14 -> 751329 | D15: =D13-D14 -> 10259568 | E15: =SUM(B15:D15) -> 15610979 | F15: =F13-F14 -> 7418365 | G15: =G13-G14 -> 6342441.8 | H15: =H13-H14 -> 10931486 | I15: =I13-I14 -> 24692293 | J15: =J13-J14 -> 11049536 | K15: =K13-K14 -> 11184271 | L15: =L13-L14 -> 0 | M15: =M13-M14 -> 22233807 | ... S15: =S13-S14 -> 62537079 | T15: =E15+I15+M15+Q15 -> 62537079 | U15: 5711669 | V15: 1646884 | W15: 16106161 | X15: 23464714 | Y15: 7867103 | Z15: 14962063 | AA15: 14671358 | AB15: 37500524 | AC15: 8563865 | AD15: 12443417 | AE15: 8021450 | AF15: 29028732 | AG15: 5409260 | AH15: 13096413 | AI15: =AI13-AI14 -> 16685159 | AJ15: =AJ13-AJ14 -> 35190832 | AK15: =AK13-AK14 -> 60965238 | AL15: =AL13-AL14 -> 89993970 | AM15: =AM13-AM14 -> 125184802 | AN15: 3428623 | AO15: 1367370 | AP15: 8185973 | AQ15: 12981966 | AR15: 7839847 | AS15: 5201974 | AT15: 11079908 | AU15: 24121729 | AV15: 4053047 | AW15: 1862304 | AX15: 4732566 | AY15: 10647917 | AZ15: 2853591 | BA15: 2755944 | BB15: 23046091 | BC15: 28655626 | BD15: 37103695 | BE15: 47751612 | BF15: 76407238 | BG15: 4416359 | BH15: 130876 | BI15: 6522093 | BJ15: 11069328 | BK15: 3181169 | BL15: 8025466 | BM15: 5311997 | BN15: 16518632 | BO15: 5535713 | BP15: 4715106 | BQ15: 6310594 | BR15: 16561413 | BS15: 1713735 | BT15: 1511649 | BU15: 11306839 | BV15: 14532223 | BW15: 27587960 | BX15: 44149373 | BY15: 58681596 | BZ15: 8769545 | CA15: 2289620 | CB15: 7110136 | CC15: 18169301 | CD15: 5784674 | CE15: 3551193 | CF15: 8319239 | CG15: 17655106 | CH15: 5316805 | CI15: 6173086 | CJ15: 843622 | CK15: 12333513 | CL15: -3657398 | CM15: 3918185 | CN15: 9199274 | CO15: 9460061 | CP15: 35824407 | CQ15: 48157920 | CR15: 57617981 | CS15: =CS13-CS14 -> -7271011 | CT15: =CT13-CT14 -> -6037456 | CU15: =CU13-CU14 -> -3376509 | CV15: =CV13-CV14 -> -16684976 | CW15: =CW13-CW14 -> -4111568 | CX15: =CX13-CX14 -> -7173080 | CY15: =CY13-CY14 -> -7513521 | CZ15: =CZ13-CZ14 -> -18798169 | ... DG15: =DG13-DG14 -> -817331 | DH15: =SUM(DE15:DG15) -> -18167590 | DI15: =CV15+CZ15 -> -35483145 | DJ15: =CV15+CZ15+DD15 -> -51924828 | DK15: =DH15+DJ15 -> -70092418 | DL15: =CR15-DK15 -> 127710399 | DM15: =DL15/DK15 -> -1.8220287 | DN15: =BY15-CR15 -> 1063615 | DO15: =DN15/CR15 -> 0.018459776 | DP15: =BF15-BY15 -> 17725642 | DQ15: =DP15/BY15 -> 0.30206476 | DR15: =AM15-BE15 -> 77433190 | DS15: =DR15/BF15 -> 1.0134274 | DT15: =C15-V15 -> -895555 | DU15: =DT15/BH15 -> -6.8427748
A16: 毛利率 | B16: =B15/B13*100 -> 7.6353773 | C16: =C15/C13*100 -> 1.415692 | D16: =D15/D13*100 -> 16.097993 | E16: =E15/E13*100 -> 8.8172504 | F16: =F15/F13*100 -> 11.012084 | G16: =G15/G13*100 -> 11.903682 | H16: =H15/H13*100 -> 12.494845 | I16: =I15/I13*100 -> 11.863595 | ... T16: =T15/T13*100 -> 11.057521 | U16: 15.455472 | V16: 3.9969346 | W16: 23.410561 | X16: 15.966951 | Y16: 18.698585 | Z16: 24.653437 | AA16: 26.186662 | AB16: 23.616592 | AC16: 16.955859 | AD16: 18.298221 | AE16: 14.841849 | AF16: 16.822749 | AG16: 11.112424 | AH16: 19.197319 | AI16: =AI15/AI13*100 -> 17.870351 | AJ16: =AJ15/AJ13*100 -> 16.736385 | AK16: =AK15/AK13*100 -> 19.939773 | AL16: =AL15/AL13*100 -> 18.815251 | AM16: =AM15/AM13*100 -> 18.180436 | AN16: 0.17039664 | AO16: 0.048118934 | AP16: 0.13398021 | AQ16: 0.11840942 | AR16: 0.15972445 | AS16: 0.15686858 | AT16: 0.18725238 | AU16: 0.17057295 | AV16: 0.13842171 | AW16: 0.075373325 | AX16: 0.15187968 | AY16: 0.12505168 | AZ16: 0.11465943 | BA16: 0.111575 | BB16: 0.28133892 | BC16: 0.21790743 | BD16: 0.14779276 | BE16: 0.14203322 | BF16: 0.16336666 | BG16: 0.28774407 | BH16: 0.0093897192 | BI16: 0.26276095 | BJ16: 0.20457902 | BK16: 0.26978129 | BL16: 0.24193009 | BM16: 0.15711047 | BN16: 0.20969407 | BO16: 0.27531848 | BP16: 0.23258547 | BQ16: 0.27399485 | BR16: 0.26117591 | BS16: 0.16869803 | BT16: 0.072568168 | BU16: 0.32941296 | BV16: 0.22249937 | BW16: 0.2076113 | BX16: 0.22491488 | BY16: 0.22431181 | BZ16: 0.21928759 | CA16: 0.1413874 | CB16: 0.28260265 | CC16: 0.22336239 | CD16: 0.2054927 | CE16: 0.1362536 | CF16: 0.23798802 | CG16: 0.19799395 | CH16: 0.22278519 | CI16: 0.30330049 | CJ16: 0.039893718 | CK16: 0.18868698 | CL16: -0.27697214 | CM16: 0.15313899 | CN16: 0.40223892 | CO16: 0.15342071 | CP16: 0.21009605 | CQ16: 0.20416335 | CR16: 0.19364767 | CS16: =CS15/CS13 -> -0.60973943 | CT16: =CT15/CT13 -> -0.27376302 | CU16: =CU15/CU13 -> -0.16345443 | CV16: =CV15/CV13 -> -0.30538676 | CW16: =CW15/CW13 -> -0.28645367 | CX16: =CX15/CX13 -> -0.42114333 | CY16: =CY15/CY13 -> -0.46449379 | CZ16: =CZ15/CZ13 -> -0.39523954 | ... DK16: =DK15/DK13 -> -0.38853065 | DL16: =CR16-DK16 -> 0.58217832 | DN16: =BY16-CR16 -> 0.030664144 | DP16: =BF16-BY16 -> -0.06094515 | DR16: =AM16-BE16 -> 18.038403 | DT16: =C16-V16 -> -2.5812426
A17: 毛利率(排除存貨評價) | B17: =(B15+B50)/B13*100 -> 12.406986 | C17: =(C15+C50)/C13*100 -> 6.6227636 | D17: =(D15+D50)/D13*100 -> 4.398127 | E17: =(E15+E50)/E13*100 -> 7.7902351 | F17: =(F15+F50)/F13*100 -> 10.13342 | G17: =(G15+G50)/G13*100 -> 13.882724 | H17: =(H15+H50)/H13*100 -> 10.813789 | I17: =(I15+I50)/I13*100 -> 11.379208 | ... T17: =(T15+T50)/T13*100 -> 10.202775 | U17: 15.504203 | V17: 12.23592 | W17: 23.050571 | X17: 18.120699 | Y17: 17.390911 | Z17: 18.471858 | AA17: 24.184503 | AB17: 20.20106 | AC17: 20.778053 | AD17: 13.413348 | AE17: 14.382794 | AF17: 15.872617 | AG17: 14.172981 | AH17: 13.110516 | AI17: 16.265261 | AJ17: 14.757339 | AK17: 19.201129 | AL17: 18.00031 | AM17: 17.010017 | AN17: 0.20416587 | AO17: 0.10294567 | AP17: 0.16580122 | AQ17: 0.1565508 | AR17: 0.13252578 | AS17: 0.11589751 | AT17: 0.19647016 | AU17: 0.15538202 | AV17: 0.16878718 | AW17: 0.16450445 | AX17: 0.19989699 | AY17: 0.17892909 | AZ17: 0.24106236 | BA17: 0.15193687 | BB17: 0.18672155 | BC17: 0.19047213 | BD17: 0.15589243 | BE17: 0.16172684 | BF17: 0.16980911 | BG17: 0.26375347 | BH17: 0.20182271 | BI17: 0.28511251 | BJ17: 0.25759829 | BK17: 0.28554014 | BL17: 0.23074908 | BM17: 0.24538193 | BN17: 0.24523114 | BR17: 0.25080501 | BS17: 0.229654 | BT17: 0.18004205 | BU17: 0.19447706 | BV17: 0.19534451 | BW17: 0.25026685 | BX17: 0.2504407 | BY17: 0.23668524 | BZ17: 0.22552895 | CA17: 0.16916939 | CB17: 0.22102634 | CC17: 0.21291634 | CD17: 0.2377633 | CE17: 0.22501943 | CF17: 0.24001178 | CG17: 0.2349199 | CK17: 0.23961398 | CL17: 0.16594513 | CM17: 0.1974323 | CN17: 0.28282911 | CO17: 0.22236307 | CP17: 0.22442302 | CQ17: 0.22863262 | CR17: 0.22733334 | DK17: =(DK15+DK50)/DK13 -> -0.39945094 | DL17: =CR17-DK17 -> 0.62678428 | DN17: =BY17-CR17 -> 0.0093518983 | DP17: =BF17-BY17 -> -0.066876132 | DR17: =AM17-BE17 -> 16.84829 | DT17: =C17-V17 -> -5.6131568
A18: 營業費用
A19: 銷售費用 | B19: ='2017 預算'!C18 -> 2682181 | C19: ='2017 預算'!F18 -> 3034578 | D19: ='2017 預算'!I18 -> 2064980 | E19: =SUM(B19:D19) -> 7781739 | F19: ='2017 預算'!O18 -> 2828716 | G19: ='2017 預算'!R18 -> 2899107 | H19: ='2017 預算'!U18 -> 3746561 | I19: =SUM(F19:H19) -> 9474384 | J19: ='2017 預算'!AA18 -> 3694714 | K19: ='2017 預算'!AD18 -> 3586817 | L19: ='2017 預算'!AG18 -> 0 | M19: =SUM(J19:L19) -> 7281531 | N19: ='2017 預算'!AM18 -> 0 | O19: ='2017 預算'!AP18 -> 0 | P19: ='2017 預算'!AS18 -> 0 | Q19: =SUM(N19:P19) -> 0 | R19: =E19+I19 -> 17256123 | S19: =E19+I19+M19 -> 24537654 | T19: =E19+I19+M19+Q19 -> 24537654 | U19: 2459333 | V19: 2826212 | W19: 2965358 | X19: 8250903 | Y19: 3069079 | Z19: 2976654 | AA19: 2698890 | AB19: 8744623 | AC19: 2959846 | AD19: 2138563 | AE19: 1289282 | AF19: 6387691 | AG19: 2838978 | AH19: 3089256 | AI19: =286031+4103644 -> 4389675 | AJ19: =6214265+4103644 -> 10317909 | AK19: 16995526 | AL19: =23383217 -> 23383217 | AM19: =29597482+4103644 -> 33701126 | AN19: 1283568 | AO19: 1374819 | AP19: 1404605 | AQ19: 4062992 | AR19: 1943674 | AS19: 1819649 | AT19: 6876572 | AU19: 10639895 | AV19: 23001712 | AW19: 1344597 | AX19: 1872372 | AY19: 26218681 | AZ19: 3235759 | BA19: 2913406 | BB19: 5724127 | BC19: 11873292 | BD19: 14702887 | BE19: 40921568 | BF19: 52794860 | BG19: 1364416 | BH19: 1307027 | BI19: 2108408 | BJ19: 4779851 | BK19: 1438051 | BL19: 1376748 | BM19: 1556292 | BN19: 4371091 | BO19: 702717 | BP19: 1445924 | BQ19: 1381829 | BR19: 3530470 | BS19: 1147933 | BT19: 1570325 | BU19: 997814 | BV19: 3716072 | BW19: 9150942 | BX19: 12681412 | BY19: 16397484 | BZ19: 1540319 | CA19: 1086538 | CB19: 1084529 | CC19: 3711386 | CD19: 1289944 | CE19: 1323887 | CF19: 1614484 | CG19: 4228315 | CH19: 1652194 | CI19: 1719947 | CJ19: 1689550 | CK19: 5061691 | CL19: 1712496 | CM19: 1462349 | CN19: 1889648 | CO19: 5064493 | CP19: 7939701 | CQ19: 13001392 | CR19: 18065885 | CS19: 1573425 | CT19: 1984506 | CU19: =[1]TWN_IS!F133 -> 2409569 | CV19: =SUM(CS19:CU19) -> 5967500 | CW19: 1555775 | CX19: 2063374 | CY19: 2768247 | CZ19: =SUM(CW19:CY19) -> 6387396 | DA19: 1779022 | DB19: 1589081 | DC19: 1805551 | DD19: =SUM(DA19:DC19) -> 5173654 | DE19: 2120284 | DF19: 1444010 | DG19: -91619 | DH19: =SUM(DE19:DG19) -> 3472675 | DI19: =CV19+CZ19 -> 12354896 | DJ19: =CV19+CZ19+DD19 -> 17528550 | DK19: =DH19+DJ19 -> 21001225 | DL19: =CR19-DK19 -> -2935340 | DM19: =DL19/DK19 -> -0.13976994 | DN19: =BY19-CR19 -> -1668401 | DO19: =DN19/CR19 -> -0.092350914 | DP19: =BF19-BY19 -> 36397376 | DQ19: =DP19/BY19 -> 2.2196927 | DR19: =AM19-BE19 -> -7220442 | DS19: =DR19/BF19 -> -0.13676411 | DT19: =C19-V19 -> 208366 | DU19: =DT19/BH19 -> 0.15941981
A20: 管理費用 | B20: ='2017 預算'!C19 -> 1755765 | C20: ='2017 預算'!F19 -> 2075875 | D20: ='2017 預算'!I19 -> 1882646 | E20: =SUM(B20:D20) -> 5714286 | F20: ='2017 預算'!O19 -> 1770950 | G20: ='2017 預算'!R19 -> 1871563 | H20: ='2017 預算'!U19 -> 1797661 | I20: =SUM(F20:H20) -> 5440174 | J20: ='2017 預算'!AA19 -> 3498119 | K20: ='2017 預算'!AD19 -> 1755224 | L20: ='2017 預算'!AG19 -> 0 | M20: =SUM(J20:L20) -> 5253343 | N20: ='2017 預算'!AM19 -> 0 | O20: ='2017 預算'!AP19 -> 0 | P20: ='2017 預算'!AS19 -> 0 | Q20: =SUM(N20:P20) -> 0 | R20: =E20+I20 -> 11154460 | S20: =E20+I20+M20 -> 16407803 | T20: =E20+I20+M20+Q20 -> 16407803 | U20: 2234226 | V20: 1643974 | W20: 2044943 | X20: 5923143 | Y20: 1736598 | Z20: 1895472 | AA20: 1827592 | AB20: 5459662 | AC20: 2349662 | AD20: 1786527 | AE20: 1612591 | AF20: 5748780 | AG20: 1658767 | AH20: 1610671 | AI20: =1273127+1575403 -> 2848530 | AJ20: =4542565+1575403 -> 6117968 | AK20: 11382805 | AL20: =17131585 -> 17131585 | AM20: =21674150+1575403 -> 23249553 | AN20: 1762901 | AO20: 2584452 | AP20: 1964971 | AQ20: 6312324 | AR20: 2617103 | AS20: 1871651 | AT20: 2003843 | AU20: 6492597 | AV20: 809714 | AW20: 1836978 | AX20: 1698177 | AY20: 4344869 | AZ20: 1696811 | BA20: 1753506 | BB20: 369588 | BC20: 3819905 | BD20: 12804921 | BE20: 17149790 | BF20: 20969695 | BG20: 1618375 | BH20: 1562878 | BI20: 1627110 | BJ20: 4808363 | BK20: 2791737 | BL20: 1687914 | BM20: 1683059 | BN20: 6162710 | BO20: 1581044 | BP20: 1536597 | BQ20: 1633501 | BR20: 4751142 | BS20: 1955586 | BT20: 1582156 | BU20: 610730 | BV20: 4148472 | BW20: 10971073 | BX20: 15722215 | BY20: 19870687 | BZ20: 1718116 | CA20: 1638839 | CB20: 1784191 | CC20: 5141146 | CD20: 1579660 | CE20: 1838434 | CF20: 2045584 | CG20: 5463678 | CH20: 1809532 | CI20: 1595935 | CJ20: 1776790 | CK20: 5182257 | CL20: 1657010 | CM20: 1711369 | CN20: 1219212 | CO20: 4587591 | CP20: 10604824 | CQ20: 15787081 | CR20: 20374672 | CS20: 1113637 | CT20: 947216 | CU20: =[1]TWN_IS!F171 -> 1006350 | CV20: =SUM(CS20:CU20) -> 3067203 | CW20: 1081393 | CX20: 934670 | CY20: 959121 | CZ20: =SUM(CW20:CY20) -> 2975184 | DA20: 932722 | DB20: 946381 | DC20: 903914 | DD20: =SUM(DA20:DC20) -> 2783017 | DE20: 1213932 | DF20: 1653241 | DG20: 1079582 | DH20: =SUM(DE20:DG20) -> 3946755 | DI20: =CV20+CZ20 -> 6042387 | DJ20: =CV20+CZ20+DD20 -> 8825404 | DK20: =DH20+DJ20 -> 12772159 | DL20: =CR20-DK20 -> 7602513 | DM20: =DL20/DK20 -> 0.59524102 | DN20: =BY20-CR20 -> -503985 | DO20: =DN20/CR20 -> -0.024735858 | DP20: =BF20-BY20 -> 1099008 | DQ20: =DP20/BY20 -> 0.055308002 | DR20: =AM20-BE20 -> 6099763 | DS20: =DR20/BF20 -> 0.29088468 | DT20: =C20-V20 -> 431901 | DU20: =DT20/BH20 -> 0.27634979
A21: 研發費用 | B21: ='2017 預算'!C20 -> 2937856 | C21: ='2017 預算'!F20 -> 2632242 | D21: ='2017 預算'!I20 -> 3208223 | E21: =SUM(B21:D21) -> 8778321 | F21: ='2017 預算'!O20 -> 3367941 | G21: ='2017 預算'!R20 -> 2995265 | H21: ='2017 預算'!U20 -> 3153532 | I21: =SUM(F21:H21) -> 9516738 | J21: ='2017 預算'!AA20 -> 3165352 | K21: ='2017 預算'!AD20 -> 3319491 | L21: ='2017 預算'!AG20 -> 0 | M21: =SUM(J21:L21) -> 6484843 | N21: ='2017 預算'!AM20 -> 0 | O21: ='2017 預算'!AP20 -> 0 | P21: ='2017 預算'!AS20 -> 0 | Q21: =SUM(N21:P21) -> 0 | R21: =E21+I21 -> 18295059 | S21: =E21+I21+M21 -> 24779902 | T21: =E21+I21+M21+Q21 -> 24779902 | U21: 2442035 | V21: 2634465 | W21: 2160422 | X21: 7236922 | Y21: 4308942 | Z21: 3656178 | AA21: 4425308 | AB21: 12390428 | AC21: 3618100 | AD21: 3061104 | AE21: 2873853 | AF21: 9553057 | AG21: 2726807 | AH21: 3337104 | AI21: =31975371-499772 -> 31475599 | AJ21: =8039282-499772 -> 7539510 | AK21: 19627350 | AL21: =29180407 -> 29180407 | AM21: =37219689-499772 -> 36719917 | AN21: 2910670 | AO21: 3444523 | AP21: 3684419 | AQ21: 10039612 | AR21: 3019120 | AS21: 3428280 | AT21: 4776909 | AU21: 11224309 | AV21: 2025847 | AW21: 3242345 | AX21: 3331627 | AY21: 8599819 | AZ21: 3225958 | BA21: 2820055 | BB21: 377947 | BC21: 6423960 | BD21: 21263921 | BE21: 29863740 | BF21: 36287700 | BG21: 1911347 | BH21: 2121988 | BI21: 2913268 | BJ21: 6946603 | BK21: 2225040 | BL21: 2903290 | BM21: 2903012 | BN21: 8031342 | BO21: 2703680 | BP21: 1899527 | BQ21: 2788059 | BR21: 7391266 | BS21: 2546454 | BT21: 2627696 | BU21: 1299213 | BV21: 6473363 | BW21: 14977945 | BX21: 22369211 | BY21: 28842574 | BZ21: 1400314 | CA21: 1421109 | CB21: 1841554 | CC21: 4662977 | CD21: 1749976 | CE21: 2233196 | CF21: 2235893 | CG21: 6219065 | CH21: 1949186 | CI21: 2276031 | CJ21: 2056502 | CK21: 6281719 | CL21: 2285323 | CM21: 2201203 | CN21: 780427 | CO21: 5266953 | CP21: 10882042 | CQ21: 17163761 | CR21: 22430714 | CS21: 2932853 | CT21: 2609909 | CU21: =[1]TWN_IS!F208 -> 2380502 | CV21: =SUM(CS21:CU21) -> 7923264 | CW21: 2754521 | CX21: 2409919 | CY21: 2308627 | CZ21: =SUM(CW21:CY21) -> 7473067 | DA21: 2670939 | DB21: 2454486 | DC21: 3401061 | DD21: =SUM(DA21:DC21) -> 8526486 | DE21: 2570156 | DF21: 1311167 | DG21: -1546310 | DH21: =SUM(DE21:DG21) -> 2335013 | DI21: =CV21+CZ21 -> 15396331 | DJ21: =CV21+CZ21+DD21 -> 23922817 | DK21: =DH21+DJ21 -> 26257830 | DL21: =CR21-DK21 -> -3827116 | DM21: =DL21/DK21 -> -0.14575142 | DN21: =BY21-CR21 -> 6411860 | DO21: =DN21/CR21 -> 0.2858518 | DP21: =BF21-BY21 -> 7445126 | DQ21: =DP21/BY21 -> 0.25812974 | DR21: =AM21-BE21 -> 6856177 | DS21: =DR21/BF21 -> 0.18893942 | DT21: =C21-V21 -> -2223 | DU21: =DT21/BH21 -> -0.0010476025
A22: 營業費用合計 | B22: =SUM(B19:B21) -> 7375802 | C22: =SUM(C19:C21) -> 7742695 | D22: =SUM(D19:D21) -> 7155849 | E22: =SUM(B22:D22) -> 22274346 | F22: =SUM(F19:F21) -> 7967607 | G22: =SUM(G19:G21) -> 7765935 | H22: =SUM(H19:H21) -> 8697754 | I22: =SUM(I19:I21) -> 24431296 | J22: =SUM(J19:J21) -> 10358185 | K22: =SUM(K19:K21) -> 8661532 | L22: =SUM(L19:L21) -> 0 | M22: =SUM(M19:M21) -> 19019717 | ... S22: =SUM(S19:S21) -> 65725359 | T22: =E22+I22+M22+Q22 -> 65725359 | U22: 7135594 | V22: 7104651 | W22: 7170723 | X22: 21410968 | Y22: 9114619 | Z22: 8528304 | AA22: 8951790 | AB22: 26594713 | AC22: 8927608 | AD22: 6986194 | AE22: 5775726 | AF22: 21689528 | AG22: 7224552 | AH22: 8037031 | AI22: =SUM(AI19:AI21) -> 38713804 | AJ22: =SUM(AJ19:AJ21) -> 23975387 | AK22: =SUM(AK19:AK21) -> 48005681 | AL22: =SUM(AL19:AL21) -> 69695209 | AM22: =SUM(AM19:AM21) -> 93670596 | AN22: 5957139 | AO22: 7403794 | AP22: 7053995 | AQ22: 20414928 | AR22: 7579897 | AS22: 7119580 | AT22: 13657324 | AU22: 28356801 | AV22: 25837273 | AW22: 6423920 | AX22: 6902176 | AY22: 39163369 | AZ22: 8158528 | BA22: 7486967 | BB22: 6471662 | BC22: 22117157 | BD22: 48771729 | BE22: 87935098 | BF22: 110052255 | BG22: 4894138 | BH22: 4991893 | BI22: 6648786 | BJ22: 16534817 | BK22: 6454828 | BL22: 5967952 | BM22: 6142363 | BN22: 18565143 | BO22: 4987441 | BP22: 4882048 | BQ22: 5803389 | BR22: 15672878 | BS22: 5649973 | BT22: 5780177 | BU22: 2907757 | BV22: 14337907 | BW22: 35099960 | BX22: 50772838 | BY22: 65110745 | BZ22: 4658749 | CA22: 4146486 | CB22: 4710274 | CC22: 13515509 | CD22: 4619580 | CE22: 5395517 | CF22: 5895961 | CG22: 15911058 | CH22: 5410912 | CI22: 5591913 | CJ22: 5522842 | CK22: 16525667 | CL22: 5654829 | CM22: 5374921 | CN22: 3889287 | CO22: 14919037 | CP22: 29426567 | CQ22: 45952234 | CR22: 60871271 | CS22: 5619915 | CT22: 5541631 | CU22: =CU19+CU20+CU21 -> 5796421 | CV22: =SUM(CS22:CU22) -> 16957967 | CW22: 5391689 | CX22: 5407963 | CY22: =SUM(CY19:CY21) -> 6035995 | CZ22: =SUM(CW22:CY22) -> 16835647 | DA22: =SUM(DA19:DA21) -> 5382683 | DB22: =SUM(DB19:DB21) -> 4989948 | DC22: =SUM(DC19:DC21) -> 6110526 | DD22: =SUM(DA22:DC22) -> 16483157 | DE22: =SUM(DE19:DE21) -> 5904372 | DF22: =SUM(DF19:DF21) -> 4408418 | DG22: =SUM(DG19:DG21) -> -558347 | DH22: =SUM(DE22:DG22) -> 9754443 | DI22: =CV22+CZ22 -> 33793614 | DJ22: =CV22+CZ22+DD22 -> 50276771 | DK22: =DH22+DJ22 -> 60031214 | DL22: =CR22-DK22 -> 840057 | DM22: =DL22/DK22 -> 0.01399367 | DN22: =BY22-CR22 -> 4239474 | DO22: =DN22/CR22 -> 0.06964655 | DP22: =BF22-BY22 -> 44941510 | DQ22: =DP22/BY22 -> 0.69023185 | DR22: =AM22-BE22 -> 5735498 | DS22: =DR22/BF22 -> 0.052116133 | DT22: =C22-V22 -> 638044 | DU22: =DT22/BH22 -> 0.12781604
A23: ▲ 營業淨利： | B23: =B15-B22 -> -2775720 | C23: =C15-C22 -> -6991366 | D23: =D15-D22 -> 3103719 | E23: =SUM(B23:D23) -> -6663367 | F23: =F15-F22 -> -549242 | G23: =G15-G22 -> -1423493.2 | H23: =H15-H22 -> 2233732 | I23: =I15-I22 -> 260996.77 | J23: =J15-J22 -> 691351 | K23: =K15-K22 -> 2522739 | L23: =L15-L22 -> 0 | M23: =M15-M22 -> 3214090 | ... S23: =S15-S22 -> -3188280.2 | T23: =E23+I23+M23+Q23 -> -3188280.2 | U23: -1423925 | V23: -5457767 | W23: 8935438 | X23: 2053746 | Y23: -1247516 | Z23: 6433759 | AA23: 5719568 | AB23: 10905811 | AC23: -363743 | AD23: 5457223 | AE23: 2245724 | AF23: 7339204 | AG23: -1815292 | AH23: 5059382 | AI23: =AI15-AI22 -> -22028645 | AJ23: =AJ15-AJ22 -> 11215445 | AK23: =AK15-AK22 -> 12959557 | AL23: =AL15-AL22 -> 20298761 | AM23: =AM15-AM22 -> 31514206 | AN23: -2528516 | AO23: -6036424 | AP23: 1131978 | AQ23: -7432962 | AR23: 259950 | AS23: -1917606 | AT23: -2577416 | AU23: -4235072 | AV23: -21784226 | AW23: -4561616 | AX23: -2169610 | AY23: -28515452 | AZ23: -5304937 | BA23: -4731023 | BB23: 16574429 | BC23: 6538469 | BD23: -11668034 | BE23: -40183486 | BF23: -33645017 | BG23: -477779 | BH23: -4861017 | BI23: -126693 | BJ23: -5465489 | BK23: -3273659 | BL23: 2057514 | BM23: -830366 | BN23: -2046511 | BO23: 548272 | BP23: -166942 | BQ23: 507205 | BR23: 888535 | BS23: -3936238 | BT23: -4268528 | BU23: 8399082 | BV23: 194316 | BW23: -7512000 | BX23: -6623465 | BY23: -6429149 | BZ23: 4110796 | CA23: -1856866 | CB23: 2399862 | CC23: 4653792 | CD23: 1165094 | CE23: -1844324 | CF23: 2423278 | CG23: 1744048 | CH23: -94107 | CI23: 581173 | CJ23: -4679220 | CK23: -4192154 | CL23: -9312227 | CM23: -1456736 | CN23: 5309987 | CO23: -5458976 | CP23: 6397840 | CQ23: 2205686 | CR23: -3253290 | CS23: -4426153 | CT23: -740005 | CU23: =CU15-CU22 -> -9172930 | CV23: =SUM(CS23:CU23) -> -14339088 | CW23: -1312761 | CX23: -2364596 | CY23: =CY15-CY22 -> -13549516 | CZ23: =SUM(CW23:CY23) -> -17226873 | DA23: =DA15-DA22 -> -3759952 | DB23: =DB15-DB22 -> -12446982 | DC23: =DC15-DC22 -> -16717906 | DD23: =SUM(DA23:DC23) -> -32924840 | DE23: =DE15-DE22 -> -17294645 | DF23: =DF15-DF22 -> -10368404 | DG23: =DG15-DG22 -> -258984 | DH23: =SUM(DE23:DG23) -> -27922033 | DI23: =CV23+CZ23 -> -31565961 | DJ23: =CV23+CZ23+DD23 -> -64490801 | DK23: =DH23+DJ23 -> -92412834 | DL23: =CR23-DK23 -> 89159544 | DM23: =DL23/DK23 -> -0.96479612 | DN23: =BY23-CR23 -> -3175859 | DO23: =DN23/CR23 -> 0.97619917 | DP23: =BF23-BY23 -> -27215868 | DQ23: =DP23/BY23 -> 4.2331991 | DR23: =AM23-BE23 -> 71697692 | DS23: =DR23/BF23 -> -2.1310048 | DT23: =C23-V23 -> -1533599 | DU23: =DT23/BH23 -> 0.31548933
A24: 營業外收入及費用
A25: 營業外收入及利益
A26: 利息收入 | B26: ='2017 預算'!C25 -> 1250 | C26: ='2017 預算'!F25 -> 1250 | D26: ='2017 預算'!I25 -> 1250 | E26: =SUM(B26:D26) -> 3750 | F26: ='2017 預算'!O25 -> 1250 | G26: ='2017 預算'!R25 -> 1250 | H26: ='2017 預算'!U25 -> 61835 | I26: =SUM(F26:H26) -> 64335 | J26: ='2017 預算'!AA25 -> 1250 | K26: ='2017 預算'!AD25 -> 1250 | L26: ='2017 預算'!AG25 -> 0 | M26: =SUM(J26:L26) -> 2500 | N26: ='2017 預算'!AM25 -> 0 | O26: ='2017 預算'!AP25 -> 0 | P26: ='2017 預算'!AS25 -> 0 | Q26: =SUM(N26:P26) -> 0 | R26: =E26+I26 -> 68085 | S26: =E26+I26+M26 -> 70585 | T26: =E26+I26+M26+Q26 -> 70585 | U26: 1598 | V26: 1542 | W26: 1542 | X26: 4682 | Y26: 1466 | Z26: 1396 | AA26: 35801 | AB26: 38663 | AC26: 1352 | AD26: 1250 | AE26: 1250 | AF26: 3852 | AG26: 1250 | AH26: 1250 | AI26: 32926 | AJ26: 35426 | AK26: 43345 | AL26: 47197 | AM26: 82623 | AN26: 71934 | AO26: 71933 | AP26: 71935 | AQ26: 215802 | AR26: 71934 | AS26: 50375 | AT26: 65030 | AU26: 187339 | AV26: 28818 | AW26: 1833 | AX26: 1834 | AY26: 32485 | AZ26: 1790 | BA26: 1811 | BB26: 38407 | BC26: 42008 | BD26: 403141 | BE26: 435626 | BF26: 477634 | BG26: 71933 | BH26: 71934 | BI26: 71935 | BJ26: 215802 | BK26: 71934 | BL26: 71934 | BM26: 89981 | BN26: 233849 | BO26: 71934 | BP26: 71933 | BQ26: 71935 | BR26: 215802 | BS26: 71934 | BT26: 71933 | BU26: 94685 | BV26: 238552 | BW26: 449651 | BX26: 665453 | BY26: 904005 | BZ26: 71933 | CA26: 72181 | CB26: 71933 | CC26: 216047 | CD26: 71933 | CE26: 71933 | CF26: 97149 | CG26: 241015 | CH26: 71935 | CI26: 71934 | CJ26: 71934 | CK26: 215803 | CL26: 71934 | CM26: 71933 | CN26: 94581 | CO26: 238448 | CP26: 457062 | CQ26: 672865 | CR26: 911313 | CS26: 66732 | CT26: 72157 | CU26: 72158 | CV26: =SUM(CS26:CU26) -> 211047 | CW26: 72157 | CX26: 72158 | CY26: 88326 | CZ26: =SUM(CW26:CY26) -> 232641 | DA26: 72158 | DB26: 72157 | DC26: 72157 | DD26: =SUM(DA26:DC26) -> 216472 | DE26: 72158 | DF26: 72157 | DG26: 93631 | DH26: =SUM(DE26:DG26) -> 237946 | DI26: =CV26+CZ26 -> 443688 | DJ26: =CV26+CZ26+DD26 -> 660160 | DK26: =DH26+DJ26 -> 898106 | DL26: =CR26-DK26 -> 13207 | DM26: =DL26/DK26 -> 0.014705391 | DN26: =BY26-CR26 -> -7308 | DO26: =BY26/CR26 -> 0.9919808 | DP26: =BF26-BY26 -> -426371 | DQ26: =DP26/BY26 -> -0.47164673 | DR26: =AM26-BE26 -> -353003 | DS26: =DR26/BF26 -> -0.7390659 | DT26: =C26-V26 -> -292 | DU26: =DT26/BH26 -> -0.0040592766
A27: 投資收益 | B27: ='2017 預算'!C26 -> 0 | C27: ='2017 預算'!F26 -> 0 | D27: ='2017 預算'!I26 -> 0 | E27: =SUM(B27:D27) -> 0 | F27: ='2017 預算'!O26 -> 0 | G27: ='2017 預算'!R26 -> 0 | H27: ='2017 預算'!U26 -> 0 | I27: =SUM(F27:H27) -> 0 | J27: ='2017 預算'!AA26 -> 0 | K27: ='2017 預算'!AD26 -> 0 | L27: ='2017 預算'!AG26 -> 0 | M27: =SUM(J27:L27) -> 0 | N27: ='2017 預算'!AM26 -> 0 | O27: ='2017 預算'!AP26 -> 0 | P27: ='2017 預算'!AS26 -> 0 | Q27: =SUM(N27:P27) -> 0 | R27: =E27+I27 -> 0 | S27: =E27+I27+M27 -> 0 | T27: =E27+I27+M27+Q27 -> 0 | U27: 0 | V27: 0 | W27: 0 | X27: 0 | Y27: 0 | Z27: 0 | AA27: 0 | AB27: 0 | AC27: 0 | AD27: 0 | AE27: 0 | AF27: 0 | AG27: 0 | AH27: 0 | AI27: 0 | AJ27: 0 | AK27: 0 | AL27: 0 | AM27: 0 | AN27: 0 | AO27: 0 | AP27: 0 | AQ27: 0 | AR27: 0 | AS27: 0 | AT27: 0 | AU27: 0 | AV27: 0 | AW27: 0 | AX27: 0 | AY27: 0 | AZ27: 0 | BA27: 0 | BB27: 0 | BC27: 0 | BD27: 0 | BE27: 0 | BF27: 0 | BI27: 0 | BJ27: 0 | BK27: 0 | BN27: 0 | BR27: 0 | BV27: 0 | BW27: 0 | BX27: 0 | BY27: 0 | BZ27: 0 | CA27: 0 | CB27: 0 | CC27: 0 | CD27: 0 | CE27: 0 | CF27: 0 | CG27: 0 | CH27: 0 | CI27: 0 | CJ27: 0 | CK27: 0 | CO27: 0 | CP27: 0 | CQ27: 0 | CR27: 0 | CS27: 0 | CT27: 0 | CU27: 0 | CV27: =SUM(CS27:CU27) -> 0 | CW27: 0 | CX27: 0 | CY27: 0 | CZ27: =SUM(CW27:CY27) -> 0 | DA27: 0 | DB27: 0 | DC27: 0 | DD27: =SUM(DA27:DC27) -> 0 | DH27: =SUM(DE27:DG27) -> 0 | DI27: =CV27+CZ27 -> 0 | DJ27: =CV27+CZ27+DD27 -> 0 | DK27: =DH27+DJ27 -> 0 | DL27: =CR27-DK27 -> 0 | DN27: =BY27-CR27 -> 0 | DP27: =BF27-BY27 -> 0 | DR27: =AM27-BE27 -> 0 | DT27: =C27-V27 -> 0
A28: 處分固定資產利益 | B28: ='2017 預算'!C27 -> 0 | C28: ='2017 預算'!F27 -> 0 | D28: ='2017 預算'!I27 -> 0 | E28: =SUM(B28:D28) -> 0 | F28: ='2017 預算'!O27 -> 0 | G28: ='2017 預算'!R27 -> 0 | H28: ='2017 預算'!U27 -> 0 | I28: =SUM(F28:H28) -> 0 | J28: ='2017 預算'!AA27 -> 0 | K28: ='2017 預算'!AD27 -> 0 | L28: ='2017 預算'!AG27 -> 0 | M28: =SUM(J28:L28) -> 0 | N28: ='2017 預算'!AM27 -> 0 | O28: ='2017 預算'!AP27 -> 0 | P28: ='2017 預算'!AS27 -> 0 | Q28: =SUM(N28:P28) -> 0 | R28: =E28+I28 -> 0 | S28: =E28+I28+M28 -> 0 | T28: =E28+I28+M28+Q28 -> 0 | U28: 0 | V28: 0 | W28: 6480 | X28: 6480 | Y28: 0 | Z28: 0 | AA28: 0 | AB28: 0 | AC28: 0 | AD28: 0 | AE28: 0 | AF28: 0 | AG28: 0 | AH28: 0 | AI28: 0 | AJ28: 0 | AK28: 6480 | AL28: 6480 | AM28: 6480 | AN28: 0 | AO28: 0 | AP28: 30762 | AQ28: 30762 | AR28: 0 | AS28: 20766 | AT28: 0 | AU28: 20766 | AV28: 0 | AW28: 0 | AX28: 0 | AY28: 0 | AZ28: 0 | BA28: 5909 | BB28: 0 | BC28: 5909 | BD28: 51528 | BE28: 51528 | BF28: 57437 | BG28: 4190 | BI28: 4857 | BJ28: 9047 | BK28: 0 | BN28: 0 | BR28: 0 | BV28: 0 | BW28: 9047 | BX28: 9047 | BY28: 9047 | BZ28: 0 | CA28: 0 | CB28: 0 | CC28: 0 | CD28: 0 | CE28: 0 | CF28: 0 | CG28: 0 | CH28: 0 | CI28: 0 | CJ28: 0 | CK28: 0 | CN28: 914 | CO28: 914 | CP28: 0 | CQ28: 0 | CR28: 914 | CS28: 0 | CT28: 0 | CU28: 0 | CV28: =SUM(CS28:CU28) -> 0 | CW28: 0 | CX28: 0 | CY28: 0 | CZ28: =SUM(CW28:CY28) -> 0 | DA28: 0 | DB28: 0 | DC28: 0 | DD28: =SUM(DA28:DC28) -> 0 | DH28: =SUM(DE28:DG28) -> 0 | DI28: =CV28+CZ28 -> 0 | DJ28: =CV28+CZ28+DD28 -> 0 | DK28: =DH28+DJ28 -> 0 | DL28: =CR28-DK28 -> 914 | DN28: =BY28-CR28 -> 8133 | DO28: =BY28/CR28-1 -> 8.8982495 | DP28: =BF28-BY28 -> 48390 | DQ28: =DP28/BY28 -> 5.3487344 | DR28: =AM28-BE28 -> -45048 | DS28: =DR28/BF28 -> -0.7843028 | DT28: =C28-V28 -> 0 | DU28: =DT28/BH28 -> #DIV/0!
A29: 處分投資利益 | B29: ='2017 預算'!C28 -> 0 | C29: ='2017 預算'!F28 -> 0 | D29: ='2017 預算'!I28 -> 0 | E29: =SUM(B29:D29) -> 0 | F29: ='2017 預算'!O28 -> 0 | G29: ='2017 預算'!R28 -> 0 | H29: ='2017 預算'!U28 -> 0 | I29: =SUM(F29:H29) -> 0 | J29: ='2017 預算'!AA28 -> 0 | K29: ='2017 預算'!AD28 -> 0 | L29: ='2017 預算'!AG28 -> 0 | M29: =SUM(J29:L29) -> 0 | N29: ='2017 預算'!AM28 -> 0 | O29: ='2017 預算'!AP28 -> 0 | P29: ='2017 預算'!AS28 -> 0 | Q29: =SUM(N29:P29) -> 0 | R29: =E29+I29 -> 0 | S29: =E29+I29+M29 -> 0 | T29: =E29+I29+M29+Q29 -> 0 | U29: 0 | V29: 0 | W29: 0 | X29: 0 | Y29: 0 | Z29: 0 | AA29: 0 | AB29: 0 | AC29: 0 | AD29: 0 | AE29: 0 | AF29: 0 | AG29: 0 | AH29: 0 | AI29: 0 | AJ29: 0 | AK29: 0 | AL29: 0 | AM29: 0 | AN29: 0 | AO29: 0 | AP29: 0 | AQ29: 0 | AR29: 0 | AS29: 0 | AT29: 0 | AU29: 0 | AV29: 0 | AW29: 0 | AX29: 0 | AY29: 0 | AZ29: 0 | BA29: 0 | BB29: 0 | BC29: 0 | BD29: 0 | BE29: 0 | BF29: 0 | BI29: 0 | BJ29: 0 | BK29: 0 | BN29: 0 | BR29: 0 | BV29: 0 | BW29: 0 | BX29: 0 | BY29: 0 | BZ29: 0 | CA29: 0 | CB29: 0 | CC29: 0 | CD29: 0 | CE29: 0 | CF29: 0 | CG29: 0 | CH29: 0 | CI29: 0 | CJ29: 0 | CK29: 0 | CO29: 0 | CP29: 0 | CQ29: 0 | CR29: 0 | CS29: 0 | CT29: 0 | CU29: 0 | CV29: =SUM(CS29:CU29) -> 0 | CW29: 0 | CX29: 0 | CY29: 0 | CZ29: =SUM(CW29:CY29) -> 0 | DA29: 0 | DB29: 0 | DC29: 0 | DD29: =SUM(DA29:DC29) -> 0 | DH29: =SUM(DE29:DG29) -> 0 | DI29: =CV29+CZ29 -> 0 | DJ29: =CV29+CZ29+DD29 -> 0 | DK29: =DH29+DJ29 -> 0 | DL29: =CR29-DK29 -> 0 | DN29: =BY29-CR29 -> 0 | DP29: =BF29-BY29 -> 0 | DR29: =AM29-BE29 -> 0 | DT29: =C29-V29 -> 0
A30: 存貨盤盈 | B30: ='2017 預算'!C29 -> 0 | C30: ='2017 預算'!F29 -> 0 | D30: ='2017 預算'!I29 -> 0 | E30: =SUM(B30:D30) -> 0 | F30: ='2017 預算'!O29 -> 0 | G30: ='2017 預算'!R29 -> 0 | H30: ='2017 預算'!U29 -> 0 | I30: =SUM(F30:H30) -> 0 | J30: ='2017 預算'!AA29 -> 0 | K30: ='2017 預算'!AD29 -> 0 | L30: ='2017 預算'!AG29 -> 0 | M30: =SUM(J30:L30) -> 0 | N30: ='2017 預算'!AM29 -> 0 | O30: ='2017 預算'!AP29 -> 0 | P30: ='2017 預算'!AS29 -> 0 | Q30: =SUM(N30:P30) -> 0 | R30: =E30+I30 -> 0 | S30: =E30+I30+M30 -> 0 | T30: =E30+I30+M30+Q30 -> 0 | U30: 0 | V30: 0 | W30: 0 | X30: 0 | Y30: 0 | Z30: 0 | AA30: 0 | AB30: 0 | AC30: 0 | AD30: 0 | AE30: 0 | AF30: 0 | AG30: 0 | AH30: 0 | AI30: 0 | AJ30: 0 | AK30: 0 | AL30: 0 | AM30: 0 | AN30: 0 | AO30: 0 | AP30: 0 | AQ30: 0 | AR30: 0 | AS30: 0 | AT30: 0 | AU30: 0 | AV30: 0 | AW30: 0 | AX30: 0 | AY30: 0 | AZ30: 0 | BA30: 0 | BB30: 0 | BC30: 0 | BD30: 0 | BE30: 0 | BF30: 0 | BI30: 0 | BJ30: 0 | BK30: 0 | BN30: 0 | BR30: 0 | BV30: 0 | BW30: 0 | BX30: 0 | BY30: 0 | BZ30: 0 | CA30: 0 | CB30: 0 | CC30: 0 | CD30: 0 | CE30: 0 | CF30: 0 | CG30: 0 | CH30: 0 | CI30: 0 | CJ30: 0 | CK30: 0 | CO30: 0 | CP30: 0 | CQ30: 0 | CR30: 0 | CS30: 0 | CT30: 0 | CU30: 0 | CV30: =SUM(CS30:CU30) -> 0 | CW30: 0 | CX30: 0 | CY30: 0 | CZ30: =SUM(CW30:CY30) -> 0 | DA30: 0 | DB30: 0 | DC30: 0 | DD30: =SUM(DA30:DC30) -> 0 | DH30: =SUM(DE30:DG30) -> 0 | DI30: =CV30+CZ30 -> 0 | DJ30: =CV30+CZ30+DD30 -> 0 | DK30: =DH30+DJ30 -> 0 | DL30: =CR30-DK30 -> 0 | DN30: =BY30-CR30 -> 0 | DP30: =BF30-BY30 -> 0 | DR30: =AM30-BE30 -> 0 | DT30: =C30-V30 -> 0
A31: 兌換利益 | B31: ='2017 預算'!C30 -> 860624 | C31: ='2017 預算'!F30 -> 930103 | D31: ='2017 預算'!I30 -> 2946964 | E31: =SUM(B31:D31) -> 4737691 | F31: ='2017 預算'!O30 -> 3612795 | G31: ='2017 預算'!R30 -> 1971131 | H31: ='2017 預算'!U30 -> 3773237 | I31: =SUM(F31:H31) -> 9357163 | J31: ='2017 預算'!AA30 -> 1126662 | K31: ='2017 預算'!AD30 -> 739833 | L31: ='2017 預算'!AG30 -> 0 | M31: =SUM(J31:L31) -> 1866495 | N31: ='2017 預算'!AM30 -> 0 | O31: ='2017 預算'!AP30 -> 0 | P31: ='2017 預算'!AS30 -> 0 | Q31: =SUM(N31:P31) -> 0 | R31: =E31+I31 -> 14094854 | S31: =E31+I31+M31 -> 15961349 | T31: =E31+I31+M31+Q31 -> 15961349 | U31: 2693672 | V31: 2124541 | W31: 914162 | X31: 5732375 | Y31: 2826308 | Z31: 2021649 | AA31: 594478 | AB31: 5442435 | AC31: 36207 | AD31: 1578743 | AE31: 1322573 | AF31: 2937523 | AG31: 1590892 | AH31: 1952388 | AI31: 2621871 | AJ31: 6165151 | AK31: 11174810 | AL31: 14112333 | AM31: 20277484 | AN31: 2016454 | AO31: 971858 | AP31: 389450 | AQ31: 3377762 | AR31: 1156880 | AS31: 2189799 | AT31: 1616760 | AU31: 4963439 | AV31: 2656680 | AW31: 5099592 | AX31: 4000727 | AY31: 11756999 | AZ31: 1820220 | BA31: 1588224 | BB31: 1090974 | BC31: 4499418 | BD31: 8341201 | BE31: 20098200 | BF31: 24597618 | BG31: 1244092 | BH31: 1274263 | BI31: 890875 | BJ31: 3409230 | BK31: 454351 | BL31: 33842 | BM31: 437724 | BN31: 925917 | BO31: 705066 | BP31: 239930 | BQ31: 1819616 | BR31: 2764612 | BS31: 1310425 | BT31: 1331589 | BU31: 2367453 | BV31: 5009467 | BW31: 4335147 | BX31: 7099759 | BY31: 12109226 | BZ31: 1559367 | CA31: 1742044 | CB31: 663010 | CC31: 3964421 | CD31: 1003807 | CE31: 2173671 | CF31: 1077115 | CG31: 4254593 | CH31: 318652 | CI31: 158556 | CJ31: 231081 | CK31: 708289 | CL31: 800699 | CM31: 1010043 | CN31: 865399 | CO31: 2676141 | CP31: 8219014 | CQ31: 8927303 | CR31: 11603444 | CS31: 886004 | CT31: 1360909 | CU31: 851406 | CV31: =SUM(CS31:CU31) -> 3098319 | CW31: 834778 | CX31: 1934883 | CY31: 1181696 | CZ31: =SUM(CW31:CY31) -> 3951357 | DA31: 678875 | DB31: 301077 | DC31: 34353 | DD31: =SUM(DA31:DC31) -> 1014305 | DE31: 1206134 | DF31: 87171 | DG31: 286929 | DH31: =SUM(DE31:DG31) -> 1580234 | DI31: =CV31+CZ31 -> 7049676 | DJ31: =CV31+CZ31+DD31 -> 8063981 | DK31: =DH31+DJ31 -> 9644215 | DL31: =CR31-DK31 -> 1959229 | DM31: =DL31/DK31 -> 0.2031507 | DN31: =BY31-CR31 -> 505782 | DO31: =BY31/CR31-1 -> 0.043588955 | DP31: =BF31-BY31 -> 12488392 | DQ31: =DP31/BY31 -> 1.0313122 | DR31: =AM31-BE31 -> 179284 | DS31: =DR31/BF31 -> 0.0072886732 | DT31: =C31-V31 -> -1194438 | DU31: =DT31/BH31 -> -0.93735595
A32: 租金收入 | B32: ='2017 預算'!C31 -> 0 | C32: ='2017 預算'!F31 -> 0 | D32: ='2017 預算'!I31 -> 0 | E32: =SUM(B32:D32) -> 0 | F32: ='2017 預算'!O31 -> 0 | G32: ='2017 預算'!R31 -> 0 | H32: ='2017 預算'!U31 -> 0 | I32: =SUM(F32:H32) -> 0 | J32: ='2017 預算'!AA31 -> 0 | K32: ='2017 預算'!AD31 -> 0 | L32: ='2017 預算'!AG31 -> 0 | M32: =SUM(J32:L32) -> 0 | N32: ='2017 預算'!AM31 -> 0 | O32: ='2017 預算'!AP31 -> 0 | P32: ='2017 預算'!AS31 -> 0 | Q32: =SUM(N32:P32) -> 0 | R32: =E32+I32 -> 0 | S32: =E32+I32+M32 -> 0 | T32: =E32+I32+M32+Q32 -> 0 | U32: 0 | V32: 0 | W32: 0 | X32: 0 | Y32: 0 | Z32: 0 | AA32: 0 | AB32: 0 | AC32: 0 | AD32: 0 | AE32: 0 | AF32: 0 | AG32: 0 | AH32: 0 | AI32: 0 | AJ32: 0 | AK32: 0 | AL32: 0 | AM32: 0 | AN32: 0 | AO32: 0 | AP32: 0 | AQ32: 0 | AR32: 0 | AS32: 0 | AT32: 0 | AU32: 0 | AV32: 0 | AW32: 0 | AX32: 0 | AY32: 0 | AZ32: 0 | BA32: 0 | BB32: 0 | BC32: 0 | BD32: 0 | BE32: 0 | BF32: 0 | BI32: 0 | BJ32: 0 | BK32: 0 | BN32: 0 | BR32: 0 | BV32: 0 | BW32: 0 | BX32: 0 | BY32: 0 | BZ32: 0 | CA32: 0 | CB32: 0 | CC32: 0 | CD32: 0 | CE32: 0 | CF32: 0 | CG32: 0 | CH32: 0 | CI32: 0 | CJ32: 0 | CK32: 0 | CO32: 0 | CP32: 0 | CQ32: 0 | CR32: 0 | CS32: 0 | CT32: 0 | CU32: 0 | CV32: =SUM(CS32:CU32) -> 0 | CW32: 0 | CX32: 0 | CY32: 0 | CZ32: =SUM(CW32:CY32) -> 0 | DA32: 0 | DB32: 0 | DC32: 0 | DD32: =SUM(DA32:DC32) -> 0 | DH32: =SUM(DE32:DG32) -> 0 | DI32: =CV32+CZ32 -> 0 | DJ32: =CV32+CZ32+DD32 -> 0 | DK32: =DH32+DJ32 -> 0 | DL32: =CR32-DK32 -> 0 | DN32: =BY32-CR32 -> 0 | DP32: =BF32-BY32 -> 0 | DR32: =AM32-BE32 -> 0 | DT32: =C32-V32 -> 0
A33: 金融資產評價利益 | B33: ='2017 預算'!C32 -> 0 | C33: ='2017 預算'!F32 -> 0 | D33: ='2017 預算'!I32 -> 0 | E33: =SUM(B33:D33) -> 0 | F33: ='2017 預算'!O32 -> 0 | G33: ='2017 預算'!R32 -> 0 | H33: ='2017 預算'!U32 -> 0 | I33: =SUM(F33:H33) -> 0 | J33: ='2017 預算'!AA32 -> 0 | K33: ='2017 預算'!AD32 -> 0 | L33: ='2017 預算'!AG32 -> 0 | M33: =SUM(J33:L33) -> 0 | N33: ='2017 預算'!AM32 -> 0 | O33: ='2017 預算'!AP32 -> 0 | P33: ='2017 預算'!AS32 -> 0 | Q33: =SUM(N33:P33) -> 0 | R33: =E33+I33 -> 0 | S33: =E33+I33+M33 -> 0 | T33: =E33+I33+M33+Q33 -> 0 | U33: 0 | V33: 0 | W33: 0 | X33: 0 | Y33: 0 | Z33: 0 | AA33: 0 | AB33: 0 | AC33: 0 | AD33: 0 | AE33: 0 | AF33: 0 | AG33: 0 | AH33: 0 | AI33: 0 | AJ33: 0 | AK33: 0 | AL33: 0 | AM33: 0 | AN33: 0 | AO33: 0 | AP33: 0 | AQ33: 0 | AR33: 0 | AS33: 0 | AT33: 0 | AU33: 0 | AV33: 0 | AW33: 0 | AX33: 0 | AY33: 0 | AZ33: 0 | BA33: 0 | BB33: 0 | BC33: 0 | BD33: 0 | BE33: 0 | BF33: 0 | BI33: 0 | BJ33: 0 | BK33: 0 | BN33: 0 | BR33: 0 | BV33: 0 | BW33: 0 | BX33: 0 | BY33: 0 | BZ33: 0 | CA33: 0 | CB33: 0 | CC33: 0 | CD33: 0 | CE33: 0 | CF33: 0 | CG33: 0 | CH33: 0 | CI33: 0 | CJ33: 0 | CK33: 0 | CO33: 0 | CP33: 0 | CQ33: 0 | CR33: 0 | CS33: 0 | CT33: 0 | CU33: 0 | CV33: =SUM(CS33:CU33) -> 0 | CW33: 0 | CX33: 0 | CY33: 0 | CZ33: =SUM(CW33:CY33) -> 0 | DA33: 0 | DB33: 0 | DC33: 0 | DD33: =SUM(DA33:DC33) -> 0 | DH33: =SUM(DE33:DG33) -> 0 | DI33: =CV33+CZ33 -> 0 | DJ33: =CV33+CZ33+DD33 -> 0 | DK33: =DH33+DJ33 -> 0 | DL33: =CR33-DK33 -> 0 | DN33: =BY33-CR33 -> 0 | DP33: =BF33-BY33 -> 0 | DR33: =AM33-BE33 -> 0 | DT33: =C33-V33 -> 0
A34: 信用卡手續費收入 | B34: ='2017 預算'!C33 -> 0 | C34: ='2017 預算'!F33 -> 0 | D34: ='2017 預算'!I33 -> 0 | E34: =SUM(B34:D34) -> 0 | F34: ='2017 預算'!O33 -> 0 | G34: ='2017 預算'!R33 -> 0 | H34: ='2017 預算'!U33 -> 0 | I34: =SUM(F34:H34) -> 0 | J34: ='2017 預算'!AA33 -> 0 | K34: ='2017 預算'!AD33 -> 0 | L34: ='2017 預算'!AG33 -> 0 | M34: =SUM(J34:L34) -> 0 | N34: ='2017 預算'!AM33 -> 0 | O34: ='2017 預算'!AP33 -> 0 | P34: ='2017 預算'!AS33 -> 0 | Q34: =SUM(N34:P34) -> 0 | R34: =E34+I34 -> 0 | S34: =E34+I34+M34 -> 0 | T34: =E34+I34+M34+Q34 -> 0 | U34: 0 | V34: 0 | W34: 0 | X34: 0 | Y34: 0 | Z34: 0 | AA34: 0 | AB34: 0 | AC34: 0 | AD34: 0 | AE34: 0 | AF34: 0 | AG34: 0 | AH34: 0 | AI34: 0 | AJ34: 0 | AK34: 0 | AL34: 0 | AM34: 0 | AN34: 0 | AO34: 0 | AP34: 0 | AQ34: 0 | AR34: 0 | AS34: 0 | AT34: 0 | AU34: 0 | AV34: 0 | AW34: 0 | AX34: 0 | AY34: 0 | AZ34: 0 | BA34: 0 | BB34: 0 | BC34: 0 | BD34: 0 | BE34: 0 | BF34: 0 | BI34: 0 | BJ34: 0 | BK34: 0 | BN34: 0 | BR34: 0 | BV34: 0 | BW34: 0 | BX34: 0 | BY34: 0 | BZ34: 0 | CA34: 0 | CB34: 0 | CC34: 0 | CD34: 0 | CE34: 0 | CF34: 0 | CG34: 0 | CH34: 0 | CI34: 0 | CJ34: 0 | CK34: 0 | CO34: 0 | CP34: 0 | CQ34: 0 | CR34: 0 | CS34: 0 | CT34: 0 | CU34: 0 | CV34: =SUM(CS34:CU34) -> 0 | CW34: 0 | CX34: 0 | CY34: 0 | CZ34: =SUM(CW34:CY34) -> 0 | DA34: 0 | DB34: 0 | DC34: 0 | DD34: =SUM(DA34:DC34) -> 0 | DH34: =SUM(DE34:DG34) -> 0 | DI34: =CV34+CZ34 -> 0 | DJ34: =CV34+CZ34+DD34 -> 0 | DK34: =DH34+DJ34 -> 0 | DL34: =CR34-DK34 -> 0 | DN34: =BY34-CR34 -> 0 | DP34: =BF34-BY34 -> 0 | DR34: =AM34-BE34 -> 0 | DT34: =C34-V34 -> 0
A35: 什項收入 | B35: ='2017 預算'!C34 -> 151618 | C35: ='2017 預算'!F34 -> 59477 | D35: ='2017 預算'!I34 -> 53695 | E35: =SUM(B35:D35) -> 264790 | F35: ='2017 預算'!O34 -> 277576 | G35: ='2017 預算'!R34 -> 239006 | H35: ='2017 預算'!U34 -> 88951 | I35: =SUM(F35:H35) -> 605533 | J35: ='2017 預算'!AA34 -> 70176 | K35: ='2017 預算'!AD34 -> 264338 | L35: ='2017 預算'!AG34 -> 0 | M35: =SUM(J35:L35) -> 334514 | N35: ='2017 預算'!AM34 -> 0 | O35: ='2017 預算'!AP34 -> 0 | P35: ='2017 預算'!AS34 -> 0 | Q35: =SUM(N35:P35) -> 0 | R35: =E35+I35 -> 870323 | S35: =E35+I35+M35 -> 1204837 | T35: =E35+I35+M35+Q35 -> 1204837 | U35: 316554 | V35: 17278 | W35: 59891 | X35: 393723 | Y35: 26161 | Z35: 30609 | AA35: 363717 | AB35: 420487 | AC35: 52290 | AD35: 254108 | AE35: 86845 | AF35: 393243 | AG35: 200602 | AH35: 136446 | AI35: =192813+4506014 -> 4698827 | AJ35: =529861+4506014 -> 5035875 | AK35: 814210 | AL35: =1207453 -> 1207453 | AM35: =1737314+4506014 -> 6243328 | AN35: 15073 | AO35: 316952 | AP35: 169202 | AQ35: 501227 | AR35: 16367 | AS35: 9525 | AT35: 11230 | AU35: 37122 | AV35: 25340 | AW35: 273025 | AX35: 9216 | AY35: 307581 | AZ35: 7620 | BA35: 19106 | BB35: 26458 | BC35: 53184 | BD35: 538349 | BE35: 845930 | BF35: 899114 | BG35: 29130 | BH35: 93336 | BI35: 27340 | BJ35: 149806 | BK35: 53409 | BL35: 173225 | BM35: 608202 | BN35: 834836 | BO35: 65715 | BP35: 541206 | BQ35: 10315 | BR35: 617236 | BS35: 109511 | BT35: 14275 | BU35: 21505 | BV35: 145291 | BW35: 984642 | BX35: 1601878 | BY35: 1747169 | BZ35: 34721 | CA35: 6283 | CB35: 78067 | CC35: 119071 | CD35: 369105 | CE35: 160457 | CF35: 116734 | CG35: 646296 | CH35: 38077 | CI35: 147416 | CJ35: 22196 | CK35: 207689 | CL35: 129784 | CM35: 257694 | CN35: 149822 | CO35: 537300 | CP35: 765367 | CQ35: 973056 | CR35: 1510356 | CS35: 134662 | CT35: 55454 | CU35: 228604 | CV35: =SUM(CS35:CU35) -> 418720 | CW35: 310500 | CX35: 36511 | CY35: 155005 | CZ35: =SUM(CW35:CY35) -> 502016 | DA35: 15926 | DB35: 205279 | DC35: 153300 | DD35: =SUM(DA35:DC35) -> 374505 | DE35: 67513 | DF35: 40935 | DG35: 188307 | DH35: =SUM(DE35:DG35) -> 296755 | DI35: =CV35+CZ35 -> 920736 | DJ35: =CV35+CZ35+DD35 -> 1295241 | DK35: =DH35+DJ35 -> 1591996 | DL35: =CR35-DK35 -> -81640 | DM35: =DL35/DK35 -> -0.051281536 | DN35: =BY35-CR35 -> 236813 | DO35: =BY35/CR35-1 -> 0.15679284 | DP35: =BF35-BY35 -> -848055 | DQ35: =DP35/BY35 -> -0.48538808 | DR35: =AM35-BE35 -> 5397398 | DS35: =DR35/BF35 -> 6.0030185 | DT35: =C35-V35 -> 42199 | DU35: =DT35/BH35 -> 0.45211923
A36: 小計 | B36: =SUM(B26:B35) -> 1013492 | C36: =SUM(C26:C35) -> 990830 | D36: =SUM(D26:D35) -> 3001909 | E36: =SUM(B36:D36) -> 5006231 | F36: =SUM(F26:F35) -> 3891621 | G36: =SUM(G26:G35) -> 2211387 | H36: =SUM(H26:H35) -> 3924023 | I36: =SUM(I26:I35) -> 10027031 | J36: =SUM(J26:J35) -> 1198088 | K36: =SUM(K26:K35) -> 1005421 | L36: =SUM(L26:L35) -> 0 | M36: =SUM(M26:M35) -> 2203509 | ... S36: =SUM(S26:S35) -> 17236771 | T36: =E36+I36+M36+Q36 -> 17236771 | U36: 3011824 | V36: 2143361 | W36: 982075 | X36: 6137260 | Y36: 2853935 | Z36: 2053654 | AA36: 993996 | AB36: 5901585 | AC36: 89849 | AD36: 1834101 | AE36: 1410668 | AF36: 3334618 | AG36: 1792744 | AH36: 2090084 | AI36: =SUM(AI26:AI35) -> 7353624 | AJ36: =SUM(AJ26:AJ35) -> 11236452 | AK36: =SUM(AK26:AK35) -> 12038845 | AL36: =SUM(AL26:AL35) -> 15373463 | AM36: =SUM(AM26:AM35) -> 26609915 | AN36: 2103461 | AO36: 1360743 | AP36: 661349 | AQ36: 4125553 | AR36: 1245181 | AS36: 2270465 | AT36: 1693020 | AU36: 5208666 | AV36: 2710838 | AW36: 5374450 | AX36: 4011777 | AY36: 12097065 | AZ36: 1829630 | BA36: 1615050 | BB36: 1155839 | BC36: 4600519 | BD36: 9334219 | BE36: 21431284 | BF36: 26031803 | BG36: 1349345 | BH36: 1439533 | BI36: 995007 | BJ36: 3783885 | BK36: 579694 | BL36: 279001 | BM36: 1135907 | BN36: 1994602 | BO36: 842715 | BP36: 853069 | BQ36: 1901866 | BR36: 3597650 | BS36: 1491870 | BT36: 1417797 | BU36: 2483643 | BV36: 5393310 | BW36: 5778487 | BX36: 9376137 | BY36: 14769447 | BZ36: 1666021 | CA36: 1820508 | CB36: 813010 | CC36: 4299539 | CD36: 1444845 | CE36: 2406061 | CF36: 1290998 | CG36: 5141904 | CH36: 428664 | CI36: 377906 | CJ36: 325211 | CK36: 1131781 | CL36: 1002417 | CM36: 1339670 | CN36: 1110716 | CO36: 3452803 | CP36: 9441443 | CQ36: 10573224 | CR36: 14026027 | CS36: 1087398 | CT36: 1488520 | CU36: =SUM(CU26:CU35) -> 1152168 | CV36: =SUM(CS36:CU36) -> 3728086 | CW36: 1217435 | CX36: 2043552 | CY36: =SUM(CY26:CY35) -> 1425027 | CZ36: =SUM(CW36:CY36) -> 4686014 | DA36: =SUM(DA26:DA35) -> 766959 | DB36: =SUM(DB26:DB35) -> 578513 | DC36: =SUM(DC26:DC35) -> 259810 | DD36: =SUM(DA36:DC36) -> 1605282 | DE36: =SUM(DE26:DE35) -> 1345805 | DF36: =SUM(DF26:DF35) -> 200263 | DG36: =SUM(DG26:DG35) -> 568867 | DH36: =SUM(DE36:DG36) -> 2114935 | DI36: =CV36+CZ36 -> 8414100 | DJ36: =CV36+CZ36+DD36 -> 10019382 | DK36: =DH36+DJ36 -> 12134317 | DL36: =CR36-DK36 -> 1891710 | DM36: =DL36/DK36 -> 0.15589753 | DN36: =BY36-CR36 -> 743420 | DO36: =BY36/CR36-1 -> 0.053002892 | DP36: =BF36-BY36 -> 11262356 | DQ36: =DP36/BY36 -> 0.76254419 | DR36: =AM36-BE36 -> 5178631 | DS36: =DR36/BF36 -> 0.19893478 | DT36: =C36-V36 -> -1152531 | DU36: =DT36/BH36 -> -0.8006284
A37: 營業外費用及損失 | BX37: 0 | CO37: 0
